<!--
Adapted from the cabinet task of the Humanoid bench:
https://github.com/carlosferrazza/humanoid-bench/blob/main/humanoid_bench/assets/tasks/cabinet.xml
-->
<mujocoinclude>
    <asset>
        <texture name="texwood" type="2d" builtin="checker" width="100" height="100" rgb1=".87 .72 .53" rgb2=".87 .72 .53" mark="edge" markrgb=".25 .17 .7"/>
        <material name="matwood" texture="texwood" texrepeat="100 100"/>
        <material name="pastel_purple" rgba="0.69 .61 .85 1" shininess="0.99" reflectance="0"/>
		<material name="apricot" rgba="0.98 .80 .69 1" shininess="0.99" reflectance="0"/>
		<material name="acqua" rgba="0.73 .83 .90 1" shininess="0.99" reflectance="0"/>
		<material name="brick_red" rgba=".79 .25 .32 1" shininess="0.99" reflectance="0"/>
    </asset>
    <worldbody>
        <geom name="cabinet_base_a" type="box" pos="0.9 0 0.25" size="0.3 0.6 0.25" material="matwood"/>
        <geom name="cabinet_back" type="box" pos="1.21 0 0.6" size="0.009 0.6 0.6" material="matwood"/>
        <body name="drawer" pos="0.9 0 0.5">
            <joint type="slide" name="drawer_slide" pos="0 0 0" axis="-1 0 0" range="0 0.45" damping="80"/>
            <geom type="box" pos="0 0 0.02" size="0.3 0.58 0.01"  mass="5" material="matwood"/>
            <geom type="box" pos="0.29 0 0.15" size="0.01 0.58 0.14"  mass="5" material="matwood"/>
            <geom type="box" pos="-0.29 0 0.15" size="0.01 0.58 0.14"  mass="5" material="matwood"/>
            <geom type="box" pos="0 0.57 0.15" size="0.3 0.01 0.14"  mass="5" material="matwood"/>
            <geom type="box" pos="0 -0.57 0.15" size="0.3 0.01 0.14"  mass="5" material="matwood"/>
            <geom type="cylinder" pos="-0.35 -0.2 0.24" size="0.02 0.05" zaxis="1 0 0" rgba=".3 .3 .3 1"/>
            <geom type="cylinder" pos="-0.35 0.2 0.24" size="0.02 0.05" zaxis="1 0 0" rgba=".3 .3 .3 1"/>
            <geom type="box" pos="-0.39 0 0.24" size="0.01 0.2 0.01" rgba=".3 .3 .3 1"/>
        </body>        
        <body name="drawer_cube_1" pos="0.9 -0.3 0.58">
            <freejoint name="free_drawer_cube"/>
            <geom type="box" pos="0 0 0" size="0.05 0.05 0.05" material="pastel_purple"/>
        </body>
        <body name="drawer_cube_2" pos="0.8 -0.1 0.58">
            <freejoint name="free_lateral_cabinet_cube"/>
            <geom type="box" pos="0 0 0" size="0.05 0.05 0.05"  material="apricot"/>
        </body>
        <body name="drawer_cube_3" pos="0.9 0.1 0.58">
            <freejoint name="free_pulling_cabinet_cube"/>
            <geom type="box" pos="0 0 0" size="0.05 0.05 0.05"  material="acqua"/>
        </body>
        <body name="drawer_cube_4" pos="0.8 0.3 0.58">
            <freejoint name="free_pullup_drawer_cube"/>
            <geom type="box" pos="0 0 0" size="0.05 0.05 0.05"  material="brick_red"/>
        </body>
    </worldbody>
</mujocoinclude>